[
  {
    "cmd": [],
    "name": "RECIPE CRASH (Uncaught exception)",
    "~followup_annotations": [
      "@@@STEP_EXCEPTION@@@",
      "The recipe has crashed at point 'Uncaught exception'!",
      "",
      "Traceback (most recent call last):",
      "  File \"RECIPE_REPO[recipe_engine]/recipe_engine/internal/engine.py\", line 375, in run_steps",
      "    raw_result = recipe_obj.run_steps(api, engine)",
      "  File \"RECIPE_REPO[recipe_engine]/recipe_engine/internal/recipe_deps.py\", line 670, in run_steps",
      "    properties_def, api=api)",
      "  File \"RECIPE_REPO[recipe_engine]/recipe_engine/internal/property_invoker.py\", line 89, in invoke_with_properties",
      "    arg_names, **additional_args)",
      "  File \"RECIPE_REPO[recipe_engine]/recipe_engine/internal/property_invoker.py\", line 52, in _invoke_with_properties",
      "    return callable_obj(*props, **additional_args)",
      "  File \"RECIPE_REPO[build]/scripts/slave/recipe_modules/math_utils/tests/mean_error.py\", line 11, in RunSteps",
      "    api.math_utils.mean([])",
      "  File \"RECIPE_REPO[build]/scripts/slave/recipe_modules/math_utils/api.py\", line 18, in mean",
      "    raise ValueError('Trying to take the mean of an empty list.')",
      "ValueError: Trying to take the mean of an empty list."
    ]
  },
  {
    "failure": {
      "humanReason": "Uncaught Exception: ValueError('Trying to take the mean of an empty list.',)"
    },
    "name": "$result"
  }
]