[
  {
    "cmd": [],
    "name": "RECIPE CRASH (Uncaught exception)",
    "~followup_annotations": [
      "@@@STEP_EXCEPTION@@@",
      "The recipe has crashed at point 'Uncaught exception'!",
      "",
      "Traceback (most recent call last):",
      "  File \"RECIPE_REPO[build]/recipes/recipe_modules/math_utils/tests/mean_error.py\", line 11, in RunSteps",
      "    api.math_utils.mean([])",
      "  File \"RECIPE_REPO[build]/recipes/recipe_modules/math_utils/api.py\", line 18, in mean",
      "    raise ValueError('Trying to take the mean of an empty list.')",
      "ValueError: Trying to take the mean of an empty list."
    ]
  },
  {
    "failure": {
      "humanReason": "Uncaught Exception: ValueError('Trying to take the mean of an empty list.',)"
    },
    "name": "$result"
  }
]